Workbook
Name Slicer_Clean_Date__Year: #N/A
Name Slicer_Product_Category: #N/A
Name Slicer_Region: #N/A

Sheet Dashboard

Sheet Region Wise Sales Analysis
A3: Row Labels | B3: Average of Clean_Sales
A4: CENTRAL | B4: 1258.8078
A5: EAST | B5: 1219.332
A6: NORTH | B6: 1246.6992
A7: SOUTH | B7: 1213.8751
A8: WEST | B8: 1246.2482
A9: Grand Total | B9: 1238.3779

Sheet Product Category Performance
A3: Row Labels | B3: Sum of Clean_Sales
A4: Electronics | B4: 3270619.6
A5: Furniture | B5: 1428950.9
A6: Office Supplies | B6: 1492318.9
A7: Grand Total | B7: 6191889.4

Sheet Monthly Sales Trend
A3: Row Labels | B3: Sum of Clean_Sales
A4: Jan | B4: 653663.49
A5: Feb | B5: 561058.56
A6: Mar | B6: 661979.52
A7: Apr | B7: 743810.91
A8: May | B8: 547740.51
A9: Jun | B9: 454813.31
A10: Jul | B10: 454415.86
A11: Aug | B11: 468583.93
A12: Sep | B12: 439960.37
A13: Oct | B13: 383109.08
A14: Nov | B14: 413740.6
A15: Dec | B15: 409013.25
A16: Grand Total | B16: 6191889.4

Sheet Department Salary Summary
A3: Row Labels | B3: Sum of Clean_Salary
A4: Finance | B4: 5224381
A5: HR | B5: 5594342
A6: IT | B6: 6331284
A7: Operations | B7: 5465744
A8: Sales | B8: 13430554
A9: Grand Total | B9: 36046305

Sheet Delivery Performance
A3: Row Labels | B3: Count of Shipment_ID
A4: Delayed | B4: 694
A5: Lost | B5: 630
A6: On Time | B6: 676
A7: Grand Total | B7: 2000

Sheet Return Analysis
A3: Row Labels | B3: Count of Return_ID
A4: Customer Changed Mind | B4: 141
A5: Damaged | B5: 144
A6: Late Delivery | B6: 157
A7: Wrong Item | B7: 158
A8: Grand Total | B8: 600

Sheet Inventory Stock Analysis
A1: Warehouse | B1: All
A3: Row Labels | B3: Count of Stock_Qty
A4: Also | B4: 3
A5: Argue | B5: 3
A6: Catch | B6: 3
A7: Character | B7: 3
A8: Cost | B8: 3
A9: Course | B9: 3
A10: Crime | B10: 3
A11: Cultural | B11: 3
A12: Hour | B12: 4
A13: Reveal | B13: 4
A14: Grand Total | B14: 32

Sheet Supplier Performance
A3: Row Labels | B3: Sum of Rating
A4: Greer, Holland and Hess | B4: 4.8
A5: Howell-George | B5: 4.7
A6: Mcintyre-Carter | B6: 5
A7: Moore-Gutierrez | B7: 4.8
A8: Steele, Wright and Martinez | B8: 5
A9: Grand Total | B9: 24.3

Sheet Shipment Cost Analysis
A3: Row Labels | B3: Average of Transport_Cost
A4: DHL | B4: 5088.5774
A5: FedEx | B5: 4923.9507
A6: TCS | B6: 4983.4737
A7: UPS | B7: 5085.7049
A8: Grand Total | B8: 5019.833

Sheet Orders
A1: Order_ID | B1: Clean_ID | C1: Customer_Name | D1: Clean_Name | E1: Region | F1: Clean_Region | G1: Product_Category | H1: Clean_Product | I1: Order_Date | J1: Clean_Date | K1: Sales_Amount | L1: Clean_Sales | M1: Sales_Classification | N1: Sales_Grade | O1: Discount_% | P1: Clean_Discount | Q1: Status | R1: Delivery_Days | S1: Custom_Shipping_Label | T1: Total Sales | V1: =SUM(L2:L5001) -> 6191889.4
A2: ORD1000 | B2: =RIGHT(A2, 4) -> 1000 | C2: Tony Gibbs | D2: =PROPER(TRIM(C2)) -> Tony Gibbs | E2: north | F2: =UPPER(TRIM(E2)) -> NORTH | G2: Electronics | H2: =PROPER(TRIM(G2)) -> Electronics | I2: 01-26-2024 | J2: 45317 | K2: 1411.4 | L2: 1411.4 | M2: =IF(L2>2500, "High Sales", "Low Sales") -> Low Sales | N2: =IF(OR(ISBLANK(L2), L2="", L2=0), "Grade C", IF(L2>=4000, "Grade A", IF(L2>=2000, "Grade B", "Grade C"))) -> Grade C | O2: 10 | P2: 10 | Q2: Delivered | R2: 11 | S2: =CONCATENATE(OrdersTable[[#This Row],[Clean_ID]],"-",OrdersTable[[#This Row],[Clean_Region]],"-",OrdersTable[[#This Row],[Clean_Product]]) -> 1000-NORTH-Electronics | T2: Regional Sales (north) | V2: =SUMIF(Orders!E:E, "North", Orders!K:K) -> 2040846.6
A3: ORD1001 | B3: =RIGHT(A3, 4) -> 1001 | C3: April Pacheco | D3: =PROPER(TRIM(C3)) -> April Pacheco | E3: north | F3: =UPPER(TRIM(E3)) -> NORTH | G3: Electronics | H3: =PROPER(TRIM(G3)) -> Electronics | I3: 27/08/2025 | J3: 45896 | K3: 207.32 | L3: 207.32 | M3: =IF(L3>2500, "High Sales", "Low Sales") -> Low Sales | N3: =IF(OR(ISBLANK(L3), L3="", L3=0), "Grade C", IF(L3>=4000, "Grade A", IF(L3>=2000, "Grade B", "Grade C"))) -> Grade C | O3: 10 | P3: 10 | Q3: Pending | R3: 9 | S3: =CONCATENATE(OrdersTable[[#This Row],[Clean_ID]],"-",OrdersTable[[#This Row],[Clean_Region]],"-",OrdersTable[[#This Row],[Clean_Product]]) -> 1001-NORTH-Electronics | T3: Category Performance(electronic sales in north) | V3: =SUMIFS(Orders!K:K, Orders!F:F, "NORTH", Orders!H:H, "Electronics") -> 1078393.2
A4: ORD1002 | B4: =RIGHT(A4, 4) -> 1002 | C4: Patrick Leon | D4: =PROPER(TRIM(C4)) -> Patrick Leon | E4: Central | F4: =UPPER(TRIM(E4)) -> CENTRAL | G4: Electronics | H4: =PROPER(TRIM(G4)) -> Electronics | I4: 2025-07-28 | J4: 45866 | L4: 0 | M4: =IF(L4>2500, "High Sales", "Low Sales") -> Low Sales | N4: =IF(OR(ISBLANK(L4), L4="", L4=0), "Grade C", IF(L4>=4000, "Grade A", IF(L4>=2000, "Grade B", "Grade C"))) -> Grade C | O4: 10 | P4: 10 | Q4: Shipped | R4: 10 | S4: =CONCATENATE(OrdersTable[[#This Row],[Clean_ID]],"-",OrdersTable[[#This Row],[Clean_Region]],"-",OrdersTable[[#This Row],[Clean_Product]]) -> 1002-CENTRAL-Electronics
A5: ORD1003 | B5: =RIGHT(A5, 4) -> 1003 | C5: Michele Johnson | D5: =PROPER(TRIM(C5)) -> Michele Johnson | E5: East | F5: =UPPER(TRIM(E5)) -> EAST | G5: Electronics | H5: =PROPER(TRIM(G5)) -> Electronics | I5: 2026-02-16 | J5: 46069 | L5: 0 | M5: =IF(L5>2500, "High Sales", "Low Sales") -> Low Sales | N5: =IF(OR(ISBLANK(L5), L5="", L5=0), "Grade C", IF(L5>=4000, "Grade A", IF(L5>=2000, "Grade B", "Grade C"))) -> Grade C | O5: 15 | P5: 15 | Q5: Pending | R5: 4 | S5: =CONCATENATE(OrdersTable[[#This Row],[Clean_ID]],"-",OrdersTable[[#This Row],[Clean_Region]],"-",OrdersTable[[#This Row],[Clean_Product]]) -> 1003-EAST-Electronics
A6: ORD1004 | B6: =RIGHT(A6, 4) -> 1004 | C6: Kimberly Peck | D6: =PROPER(TRIM(C6)) -> Kimberly Peck | E6: East | F6: =UPPER(TRIM(E6)) -> EAST | G6: Electronics | H6: =PROPER(TRIM(G6)) -> Electronics | I6: 04/04/2024 | J6: 45386 | L6: 0 | M6: =IF(L6>2500, "High Sales", "Low Sales") -> Low Sales | N6: =IF(OR(ISBLANK(L6), L6="", L6=0), "Grade C", IF(L6>=4000, "Grade A", IF(L6>=2000, "Grade B", "Grade C"))) -> Grade C | P6: 0 | Q6: Cancelled | R6: 13 | S6: =CONCATENATE(OrdersTable[[#This Row],[Clean_ID]],"-",OrdersTable[[#This Row],[Clean_Region]],"-",OrdersTable[[#This Row],[Clean_Product]]) -> 1004-EAST-Electronics
A7: ORD1005 | B7: =RIGHT(A7, 4) -> 1005 | D7: =PROPER(TRIM(C7)) | E7: North | F7: =UPPER(TRIM(E7)) -> NORTH | G7: electronics | H7: =PROPER(TRIM(G7)) -> Electronics | I7: 2025-07-03 | J7: 45841 | L7: 0 | M7: =IF(L7>2500, "High Sales", "Low Sales") -> Low Sales | N7: =IF(OR(ISBLANK(L7), L7="", L7=0), "Grade C", IF(L7>=4000, "Grade A", IF(L7>=2000, "Grade B", "Grade C"))) -> Grade C | O7: 5 | P7: 5 | Q7: Returned | R7: 5 | S7: =CONCATENATE(OrdersTable[[#This Row],[Clean_ID]],"-",OrdersTable[[#This Row],[Clean_Region]],"-",OrdersTable[[#This Row],[Clean_Product]]) -> 1005-NORTH-Electronics
A8: ORD1006 | B8: =RIGHT(A8, 4) -> 1006 | C8: Jonathan Sanchez | D8: =PROPER(TRIM(C8)) -> Jonathan Sanchez | E8: north | F8: =UPPER(TRIM(E8)) -> NORTH | G8: Office Supplies | H8: =PROPER(TRIM(G8)) -> Office Supplies | I8: 2025-08-14 | J8: 45883 | K8: 3537.63 | L8: 3537.63 | M8: =IF(L8>2500, "High Sales", "Low Sales") -> High Sales | N8: =IF(OR(ISBLANK(L8), L8="", L8=0), "Grade C", IF(L8>=4000, "Grade A", IF(L8>=2000, "Grade B", "Grade C"))) -> Grade B | O8: 10 | P8: 10 | Q8: Cancelled | R8: 2 | S8: =CONCATENATE(OrdersTable[[#This Row],[Clean_ID]],"-",OrdersTable[[#This Row],[Clean_Region]],"-",OrdersTable[[#This Row],[Clean_Product]]) -> 1006-NORTH-Office Supplies
A9: ORD1007 | B9: =RIGHT(A9, 4) -> 1007 | C9: Candice Lewis | D9: =PROPER(TRIM(C9)) -> Candice Lewis | E9: South | F9: =UPPER(TRIM(E9)) -> SOUTH | G9: Electronics | H9: =PROPER(TRIM(G9)) -> Electronics | I9: 24/01/2025 | J9: 45681 | L9: 0 | M9: =IF(L9>2500, "High Sales", "Low Sales") -> Low Sales | N9: =IF(OR(ISBLANK(L9), L9="", L9=0), "Grade C", IF(L9>=4000, "Grade A", IF(L9>=2000, "Grade B", "Grade C"))) -> Grade C | O9: 10 | P9: 10 | Q9: Cancelled | R9: 6 | S9: =CONCATENATE(OrdersTable[[#This Row],[Clean_ID]],"-",OrdersTable[[#This Row],[Clean_Region]],"-",OrdersTable[[#This Row],[Clean_Product]]) -> 1007-SOUTH-Electronics
A10: ORD1008 | B10: =RIGHT(A10, 4) -> 1008 | C10: Jessica Torres | D10: =PROPER(TRIM(C10)) -> Jessica Torres | E10: South | F10: =UPPER(TRIM(E10)) -> SOUTH | G10: Office Supplies | H10: =PROPER(TRIM(G10)) -> Office Supplies | I10: 12-19-2025 | J10: 46010 | K10: 3257.78 | L10: 3257.78 | M10: =IF(L10>2500, "High Sales", "Low Sales") -> High Sales | N10: =IF(OR(ISBLANK(L10), L10="", L10=0), "Grade C", IF(L10>=4000, "Grade A", IF(L10>=2000, "Grade B", "Grade C"))) -> Grade B | P10: 0 | Q10: Pending | R10: 3 | S10: =CONCATENATE(OrdersTable[[#This Row],[Clean_ID]],"-",OrdersTable[[#This Row],[Clean_Region]],"-",OrdersTable[[#This Row],[Clean_Product]]) -> 1008-SOUTH-Office Supplies
A11: ORD1009 | B11: =RIGHT(A11, 4) -> 1009 | C11: Arthur Perry | D11: =PROPER(TRIM(C11)) -> Arthur Perry | E11: West | F11: =UPPER(TRIM(E11)) -> WEST | G11: electronics | H11: =PROPER(TRIM(G11)) -> Electronics | I11: 10-03-2024 | J11: 45568 | K11: 3456.4 | L11: 3456.4 | M11: =IF(L11>2500, "High Sales", "Low Sales") -> High Sales | N11: =IF(OR(ISBLANK(L11), L11="", L11=0), "Grade C", IF(L11>=4000, "Grade A", IF(L11>=2000, "Grade B", "Grade C"))) -> Grade B | O11: 15 | P11: 15 | Q11: Delivered | R11: 4 | S11: =CONCATENATE(OrdersTable[[#This Row],[Clean_ID]],"-",OrdersTable[[#This Row],[Clean_Region]],"-",OrdersTable[[#This Row],[Clean_Product]]) -> 1009-WEST-Electronics
A12: ORD1010 | B12: =RIGHT(A12, 4) -> 1010 | C12: Justin Gonzalez | D12: =PROPER(TRIM(C12)) -> Justin Gonzalez | E12: North | F12: =UPPER(TRIM(E12)) -> NORTH | G12: Office Supplies | H12: =PROPER(TRIM(G12)) -> Office Supplies | I12: 14/02/2025 | J12: 45702 | K12: N/A | L12: 0 | M12: =IF(L12>2500, "High Sales", "Low Sales") -> Low Sales | N12: =IF(OR(ISBLANK(L12), L12="", L12=0), "Grade C", IF(L12>=4000, "Grade A", IF(L12>=2000, "Grade B", "Grade C"))) -> Grade C | O12: 10 | P12: 10 | Q12: Shipped | R12: 7 | S12: =CONCATENATE(OrdersTable[[#This Row],[Clean_ID]],"-",OrdersTable[[#This Row],[Clean_Region]],"-",OrdersTable[[#This Row],[Clean_Product]]) -> 1010-NORTH-Office Supplies
A13: ORD1011 | B13: =RIGHT(A13, 4) -> 1011 | C13: Donald Mills | D13: =PROPER(TRIM(C13)) -> Donald Mills | E13: north | F13: =UPPER(TRIM(E13)) -> NORTH | G13: electronics | H13: =PROPER(TRIM(G13)) -> Electronics | I13: 26/05/2024 | J13: 45438 | L13: 0 | M13: =IF(L13>2500, "High Sales", "Low Sales") -> Low Sales | N13: =IF(OR(ISBLANK(L13), L13="", L13=0), "Grade C", IF(L13>=4000, "Grade A", IF(L13>=2000, "Grade B", "Grade C"))) -> Grade C | P13: 0 | Q13: Shipped | R13: 15 | S13: =CONCATENATE(OrdersTable[[#This Row],[Clean_ID]],"-",OrdersTable[[#This Row],[Clean_Region]],"-",OrdersTable[[#This Row],[Clean_Product]]) -> 1011-NORTH-Electronics
A14: ORD1012 | B14: =RIGHT(A14, 4) -> 1012 | C14: Thomas Montgomery | D14: =PROPER(TRIM(C14)) -> Thomas Montgomery | E14: Central | F14: =UPPER(TRIM(E14)) -> CENTRAL | G14: electronics | H14: =PROPER(TRIM(G14)) -> Electronics | I14: 2025-01-05 | J14: 45662 | K14: 4986.76 | L14: 4986.76 | M14: =IF(L14>2500, "High Sales", "Low Sales") -> High Sales | N14: =IF(OR(ISBLANK(L14), L14="", L14=0), "Grade C", IF(L14>=4000, "Grade A", IF(L14>=2000, "Grade B", "Grade C"))) -> Grade A | P14: 0 | Q14: Shipped | R14: 2 | S14: =CONCATENATE(OrdersTable[[#This Row],[Clean_ID]],"-",OrdersTable[[#This Row],[Clean_Region]],"-",OrdersTable[[#This Row],[Clean_Product]]) -> 1012-CENTRAL-Electronics
A15: ORD1013 | B15: =RIGHT(A15, 4) -> 1013 | C15: John Hernandez | D15: =PROPER(TRIM(C15)) -> John Hernandez | E15: North | F15: =UPPER(TRIM(E15)) -> NORTH | G15: Electronics | H15: =PROPER(TRIM(G15)) -> Electronics | I15: 06-05-2024 | J15: 45448 | L15: 0 | M15: =IF(L15>2500, "High Sales", "Low Sales") -> Low Sales | N15: =IF(OR(ISBLANK(L15), L15="", L15=0), "Grade C", IF(L15>=4000, "Grade A", IF(L15>=2000, "Grade B", "Grade C"))) -> Grade C | P15: 0 | Q15: Delivered | R15: 7 | S15: =CONCATENATE(OrdersTable[[#This Row],[Clean_ID]],"-",OrdersTable[[#This Row],[Clean_Region]],"-",OrdersTable[[#This Row],[Clean_Product]]) -> 1013-NORTH-Electronics
A16: ORD1014 | B16: =RIGHT(A16, 4) -> 1014 | C16: Paul Garza | D16: =PROPER(TRIM(C16)) -> Paul Garza | E16: West | F16: =UPPER(TRIM(E16)) -> WEST | G16: electronics | H16: =PROPER(TRIM(G16)) -> Electronics | I16: 25/06/2025 | J16: 45833 | K16: 4856.84 | L16: 4856.84 | M16: =IF(L16>2500, "High Sales", "Low Sales") -> High Sales | N16: =IF(OR(ISBLANK(L16), L16="", L16=0), "Grade C", IF(L16>=4000, "Grade A", IF(L16>=2000, "Grade B", "Grade C"))) -> Grade A | O16: 5 | P16: 5 | Q16: Returned | R16: 13 | S16: =CONCATENATE(OrdersTable[[#This Row],[Clean_ID]],"-",OrdersTable[[#This Row],[Clean_Region]],"-",OrdersTable[[#This Row],[Clean_Product]]) -> 1014-WEST-Electronics
A17: ORD1015 | B17: =RIGHT(A17, 4) -> 1015 | C17: Matthew Alvarez | D17: =PROPER(TRIM(C17)) -> Matthew Alvarez | E17: East | F17: =UPPER(TRIM(E17)) -> EAST | G17: Office Supplies | H17: =PROPER(TRIM(G17)) -> Office Supplies | I17: 24/04/2024 | J17: 45406 | L17: 0 | M17: =IF(L17>2500, "High Sales", "Low Sales") -> Low Sales | N17: =IF(OR(ISBLANK(L17), L17="", L17=0), "Grade C", IF(L17>=4000, "Grade A", IF(L17>=2000, "Grade B", "Grade C"))) -> Grade C | O17: 5 | P17: 5 | Q17: Cancelled | R17: 9 | S17: =CONCATENATE(OrdersTable[[#This Row],[Clean_ID]],"-",OrdersTable[[#This Row],[Clean_Region]],"-",OrdersTable[[#This Row],[Clean_Product]]) -> 1015-EAST-Office Supplies
A18: ORD1016 | B18: =RIGHT(A18, 4) -> 1016 | C18: Troy Cortez | D18: =PROPER(TRIM(C18)) -> Troy Cortez | E18: South | F18: =UPPER(TRIM(E18)) -> SOUTH | G18: Electronics | H18: =PROPER(TRIM(G18)) -> Electronics | I18: 02/10/2025 | J18: 45698 | K18: 4216.26 | L18: 4216.26 | M18: =IF(L18>2500, "High Sales", "Low Sales") -> High Sales | N18: =IF(OR(ISBLANK(L18), L18="", L18=0), "Grade C", IF(L18>=4000, "Grade A", IF(L18>=2000, "Grade B", "Grade C"))) -> Grade A | O18: 10 | P18: 10 | Q18: Cancelled | R18: 13 | S18: =CONCATENATE(OrdersTable[[#This Row],[Clean_ID]],"-",OrdersTable[[#This Row],[Clean_Region]],"-",OrdersTable[[#This Row],[Clean_Product]]) -> 1016-SOUTH-Electronics
A19: ORD1017 | B19: =RIGHT(A19, 4) -> 1017 | C19: Thomas Walls | D19: =PROPER(TRIM(C19)) -> Thomas Walls | E19: South | F19: =UPPER(TRIM(E19)) -> SOUTH | G19: Electronics | H19: =PROPER(TRIM(G19)) -> Electronics | I19: 05/09/2025 | J19: 45786 | K19: 2468.6 | L19: 2468.6 | M19: =IF(L19>2500, "High Sales", "Low Sales") -> Low Sales | N19: =IF(OR(ISBLANK(L19), L19="", L19=0), "Grade C", IF(L19>=4000, "Grade A", IF(L19>=2000, "Grade B", "Grade C"))) -> Grade B | O19: 15 | P19: 15 | Q19: Cancelled | R19: 4 | S19: =CONCATENATE(OrdersTable[[#This Row],[Clean_ID]],"-",OrdersTable[[#This Row],[Clean_Region]],"-",OrdersTable[[#This Row],[Clean_Product]]) -> 1017-SOUTH-Electronics
A20: ORD1018 | B20: =RIGHT(A20, 4) -> 1018 | C20: Jon Lee | D20: =PROPER(TRIM(C20)) -> Jon Lee | E20: North | F20: =UPPER(TRIM(E20)) -> NORTH | G20: Furniture | H20: =PROPER(TRIM(G20)) -> Furniture | I20: 2025-08-03 | J20: 45872 | L20: 0 | M20: =IF(L20>2500, "High Sales", "Low Sales") -> Low Sales | N20: =IF(OR(ISBLANK(L20), L20="", L20=0), "Grade C", IF(L20>=4000, "Grade A", IF(L20>=2000, "Grade B", "Grade C"))) -> Grade C | O20: 5 | P20: 5 | Q20: Returned | R20: 13 | S20: =CONCATENATE(OrdersTable[[#This Row],[Clean_ID]],"-",OrdersTable[[#This Row],[Clean_Region]],"-",OrdersTable[[#This Row],[Clean_Product]]) -> 1018-NORTH-Furniture
A21: ORD1019 | B21: =RIGHT(A21, 4) -> 1019 | C21: Christopher Mueller | D21: =PROPER(TRIM(C21)) -> Christopher Mueller | E21: South | F21: =UPPER(TRIM(E21)) -> SOUTH | G21: Furniture | H21: =PROPER(TRIM(G21)) -> Furniture | I21: 06/11/2025 | J21: 45819 | K21: 4736.9 | L21: 4736.9 | M21: =IF(L21>2500, "High Sales", "Low Sales") -> High Sales | N21: =IF(OR(ISBLANK(L21), L21="", L21=0), "Grade C", IF(L21>=4000, "Grade A", IF(L21>=2000, "Grade B", "Grade C"))) -> Grade A | O21: 15 | P21: 15 | Q21: Returned | R21: 14 | S21: =CONCATENATE(OrdersTable[[#This Row],[Clean_ID]],"-",OrdersTable[[#This Row],[Clean_Region]],"-",OrdersTable[[#This Row],[Clean_Product]]) -> 1019-SOUTH-Furniture
A22: ORD1020 | B22: =RIGHT(A22, 4) -> 1020 | C22: Leslie Moore | D22: =PROPER(TRIM(C22)) -> Leslie Moore | E22: Central | F22: =UPPER(TRIM(E22)) -> CENTRAL | G22: electronics | H22: =PROPER(TRIM(G22)) -> Electronics | I22: 08-04-2024 | J22: 45508 | K22: 3788.56 | L22: 3788.56 | M22: =IF(L22>2500, "High Sales", "Low Sales") -> High Sales | N22: =IF(OR(ISBLANK(L22), L22="", L22=0), "Grade C", IF(L22>=4000, "Grade A", IF(L22>=2000, "Grade B", "Grade C"))) -> Grade B | O22: 15 | P22: 15 | Q22: Shipped | R22: 11 | S22: =CONCATENATE(OrdersTable[[#This Row],[Clean_ID]],"-",OrdersTable[[#This Row],[Clean_Region]],"-",OrdersTable[[#This Row],[Clean_Product]]) -> 1020-CENTRAL-Electronics
A23: ORD1021 | B23: =RIGHT(A23, 4) -> 1021 | C23: Frances Mitchell | D23: =PROPER(TRIM(C23)) -> Frances Mitchell | E23: north | F23: =UPPER(TRIM(E23)) -> NORTH | G23: Office Supplies | H23: =PROPER(TRIM(G23)) -> Office Supplies | I23: 03-24-2025 | J23: 45740 | K23: 2284.86 | L23: 2284.86 | M23: =IF(L23>2500, "High Sales", "Low Sales") -> Low Sales | N23: =IF(OR(ISBLANK(L23), L23="", L23=0), "Grade C", IF(L23>=4000, "Grade A", IF(L23>=2000, "Grade B", "Grade C"))) -> Grade B | O23: 10 | P23: 10 | Q23: Delivered | R23: 6 | S23: =CONCATENATE(OrdersTable[[#This Row],[Clean_ID]],"-",OrdersTable[[#This Row],[Clean_Region]],"-",OrdersTable[[#This Row],[Clean_Product]]) -> 1021-NORTH-Office Supplies
A24: ORD1022 | B24: =RIGHT(A24, 4) -> 1022 | C24: Miguel Smith | D24: =PROPER(TRIM(C24)) -> Miguel Smith | E24: North | F24: =UPPER(TRIM(E24)) -> NORTH | G24: Furniture | H24: =PROPER(TRIM(G24)) -> Furniture | I24: 2025-08-25 | J24: 45894 | K24: 85.59 | L24: 85.59 | M24: =IF(L24>2500, "High Sales", "Low Sales") -> Low Sales | N24: =IF(OR(ISBLANK(L24), L24="", L24=0), "Grade C", IF(L24>=4000, "Grade A", IF(L24>=2000, "Grade B", "Grade C"))) -> Grade C | O24: 10 | P24: 10 | Q24: Delivered | R24: 15 | S24: =CONCATENATE(OrdersTable[[#This Row],[Clean_ID]],"-",OrdersTable[[#This Row],[Clean_Region]],"-",OrdersTable[[#This Row],[Clean_Product]]) -> 1022-NORTH-Furniture
A25: ORD1023 | B25: =RIGHT(A25, 4) -> 1023 | C25: Edward Johnson | D25: =PROPER(TRIM(C25)) -> Edward Johnson | E25: North | F25: =UPPER(TRIM(E25)) -> NORTH | G25: Office Supplies | H25: =PROPER(TRIM(G25)) -> Office Supplies | I25: 03-13-2024 | J25: 45364 | L25: 0 | M25: =IF(L25>2500, "High Sales", "Low Sales") -> Low Sales | N25: =IF(OR(ISBLANK(L25), L25="", L25=0), "Grade C", IF(L25>=4000, "Grade A", IF(L25>=2000, "Grade B", "Grade C"))) -> Grade C | O25: 10 | P25: 10 | Q25: Returned | R25: 3 | S25: =CONCATENATE(OrdersTable[[#This Row],[Clean_ID]],"-",OrdersTable[[#This Row],[Clean_Region]],"-",OrdersTable[[#This Row],[Clean_Product]]) -> 1023-NORTH-Office Supplies
A26: ORD1024 | B26: =RIGHT(A26, 4) -> 1024 | C26: Aaron Young | D26: =PROPER(TRIM(C26)) -> Aaron Young | E26: north | F26: =UPPER(TRIM(E26)) -> NORTH | G26: electronics | H26: =PROPER(TRIM(G26)) -> Electronics | I26: 05/09/2024 | J26: 45421 | K26: 4047.11 | L26: 4047.11 | M26: =IF(L26>2500, "High Sales", "Low Sales") -> High Sales | N26: =IF(OR(ISBLANK(L26), L26="", L26=0), "Grade C", IF(L26>=4000, "Grade A", IF(L26>=2000, "Grade B", "Grade C"))) -> Grade A | O26: 5 | P26: 5 | Q26: Delivered | R26: 11 | S26: =CONCATENATE(OrdersTable[[#This Row],[Clean_ID]],"-",OrdersTable[[#This Row],[Clean_Region]],"-",OrdersTable[[#This Row],[Clean_Product]]) -> 1024-NORTH-Electronics
A27: ORD1025 | B27: =RIGHT(A27, 4) -> 1025 | C27: Julie Bentley | D27: =PROPER(TRIM(C27)) -> Julie Bentley | E27: West | F27: =UPPER(TRIM(E27)) -> WEST | G27: Office Supplies | H27: =PROPER(TRIM(G27)) -> Office Supplies | I27: 09/03/2025 | J27: 45903 | K27: 2361.77 | L27: 2361.77 | M27: =IF(L27>2500, "High Sales", "Low Sales") -> Low Sales | N27: =IF(OR(ISBLANK(L27), L27="", L27=0), "Grade C", IF(L27>=4000, "Grade A", IF(L27>=2000, "Grade B", "Grade C"))) -> Grade B | O27: 5 | P27: 5 | Q27: Delivered | R27: 7 | S27: =CONCATENATE(OrdersTable[[#This Row],[Clean_ID]],"-",OrdersTable[[#This Row],[Clean_Region]],"-",OrdersTable[[#This Row],[Clean_Product]]) -> 1025-WEST-Office Supplies
A28: ORD1026 | B28: =RIGHT(A28, 4) -> 1026 | C28: Ray Mckinney | D28: =PROPER(TRIM(C28)) -> Ray Mckinney | E28: north | F28: =UPPER(TRIM(E28)) -> NORTH | G28: Office Supplies | H28: =PROPER(TRIM(G28)) -> Office Supplies | I28: 2026-03-30 | J28: 46111 | K28: 1280.85 | L28: 1280.85 | M28: =IF(L28>2500, "High Sales", "Low Sales") -> Low Sales | N28: =IF(OR(ISBLANK(L28), L28="", L28=0), "Grade C", IF(L28>=4000, "Grade A", IF(L28>=2000, "Grade B", "Grade C"))) -> Grade C | P28: 0 | Q28: Shipped | R28: 3 | S28: =CONCATENATE(OrdersTable[[#This Row],[Clean_ID]],"-",OrdersTable[[#This Row],[Clean_Region]],"-",OrdersTable[[#This Row],[Clean_Product]]) -> 1026-NORTH-Office Supplies
A29: ORD1027 | B29: =RIGHT(A29, 4) -> 1027 | C29: Nicole Berry | D29: =PROPER(TRIM(C29)) -> Nicole Berry | E29: West | F29: =UPPER(TRIM(E29)) -> WEST | G29: Furniture | H29: =PROPER(TRIM(G29)) -> Furniture | I29: 12/10/2024 | J29: 45636 | K29: 1286.54 | L29: 1286.54 | M29: =IF(L29>2500, "High Sales", "Low Sales") -> Low Sales | N29: =IF(OR(ISBLANK(L29), L29="", L29=0), "Grade C", IF(L29>=4000, "Grade A", IF(L29>=2000, "Grade B", "Grade C"))) -> Grade C | O29: 20 | P29: 20 | Q29: Returned | R29: 2 | S29: =CONCATENATE(OrdersTable[[#This Row],[Clean_ID]],"-",OrdersTable[[#This Row],[Clean_Region]],"-",OrdersTable[[#This Row],[Clean_Product]]) -> 1027-WEST-Furniture
A30: ORD1028 | B30: =RIGHT(A30, 4) -> 1028 | C30: Christina Hill | D30: =PROPER(TRIM(C30)) -> Christina Hill | E30: North | F30: =UPPER(TRIM(E30)) -> NORTH | G30: Electronics | H30: =PROPER(TRIM(G30)) -> Electronics | I30: 2024-04-05 | J30: 45387 | L30: 0 | M30: =IF(L30>2500, "High Sales", "Low Sales") -> Low Sales | N30: =IF(OR(ISBLANK(L30), L30="", L30=0), "Grade C", IF(L30>=4000, "Grade A", IF(L30>=2000, "Grade B", "Grade C"))) -> Grade C | O30: 20 | P30: 20 | Q30: Pending | R30: 14 | S30: =CONCATENATE(OrdersTable[[#This Row],[Clean_ID]],"-",OrdersTable[[#This Row],[Clean_Region]],"-",OrdersTable[[#This Row],[Clean_Product]]) -> 1028-NORTH-Electronics
A31: ORD1029 | B31: =RIGHT(A31, 4) -> 1029 | C31: Kevin Buck | D31: =PROPER(TRIM(C31)) -> Kevin Buck | E31: West | F31: =UPPER(TRIM(E31)) -> WEST | G31: Electronics | H31: =PROPER(TRIM(G31)) -> Electronics | I31: 17/06/2024 | J31: 45460 | L31: 0 | M31: =IF(L31>2500, "High Sales", "Low Sales") -> Low Sales | N31: =IF(OR(ISBLANK(L31), L31="", L31=0), "Grade C", IF(L31>=4000, "Grade A", IF(L31>=2000, "Grade B", "Grade C"))) -> Grade C | O31: 15 | P31: 15 | Q31: Shipped | R31: 5 | S31: =CONCATENATE(OrdersTable[[#This Row],[Clean_ID]],"-",OrdersTable[[#This Row],[Clean_Region]],"-",OrdersTable[[#This Row],[Clean_Product]]) -> 1029-WEST-Electronics
A32: ORD1030 | B32: =RIGHT(A32, 4) -> 1030 | C32: Kenneth Johnson | D32: =PROPER(TRIM(C32)) -> Kenneth Johnson | E32: West | F32: =UPPER(TRIM(E32)) -> WEST | G32: electronics | H32: =PROPER(TRIM(G32)) -> Electronics | I32: 2024-06-07 | J32: 45450 | K32: 1518.7 | L32: 1518.7 | M32: =IF(L32>2500, "High Sales", "Low Sales") -> Low Sales | N32: =IF(OR(ISBLANK(L32), L32="", L32=0), "Grade C", IF(L32>=4000, "Grade A", IF(L32>=2000, "Grade B", "Grade C"))) -> Grade C | P32: 0 | Q32: Returned | R32: 1 | S32: =CONCATENATE(OrdersTable[[#This Row],[Clean_ID]],"-",OrdersTable[[#This Row],[Clean_Region]],"-",OrdersTable[[#This Row],[Clean_Product]]) -> 1030-WEST-Electronics
A33: ORD1031 | B33: =RIGHT(A33, 4) -> 1031 | C33: Michael Davis | D33: =PROPER(TRIM(C33)) -> Michael Davis | E33: north | F33: =UPPER(TRIM(E33)) -> NORTH | G33: Office Supplies | H33: =PROPER(TRIM(G33)) -> Office Supplies | I33: 2024-02-28 | J33: 45350 | K33: 2941.68 | L33: 2941.68 | M33: =IF(L33>2500, "High Sales", "Low Sales") -> High Sales | N33: =IF(OR(ISBLANK(L33), L33="", L33=0), "Grade C", IF(L33>=4000, "Grade A", IF(L33>=2000, "Grade B", "Grade C"))) -> Grade B | O33: 5 | P33: 5 | Q33: Returned | R33: 2 | S33: =CONCATENATE(OrdersTable[[#This Row],[Clean_ID]],"-",OrdersTable[[#This Row],[Clean_Region]],"-",OrdersTable[[#This Row],[Clean_Product]]) -> 1031-NORTH-Office Supplies
A34: ORD1032 | B34: =RIGHT(A34, 4) -> 1032 | C34: Madeline Powell | D34: =PROPER(TRIM(C34)) -> Madeline Powell | E34: South | F34: =UPPER(TRIM(E34)) -> SOUTH | G34: Electronics | H34: =PROPER(TRIM(G34)) -> Electronics | I34: 2025-09-01 | J34: 45901 | K34: 3392.3 | L34: 3392.3 | M34: =IF(L34>2500, "High Sales", "Low Sales") -> High Sales | N34: =IF(OR(ISBLANK(L34), L34="", L34=0), "Grade C", IF(L34>=4000, "Grade A", IF(L34>=2000, "Grade B", "Grade C"))) -> Grade B | O34: 20 | P34: 20 | Q34: Delivered | R34: 15 | S34: =CONCATENATE(OrdersTable[[#This Row],[Clean_ID]],"-",OrdersTable[[#This Row],[Clean_Region]],"-",OrdersTable[[#This Row],[Clean_Product]]) -> 1032-SOUTH-Electronics
A35: ORD1033 | B35: =RIGHT(A35, 4) -> 1033 | C35: Kelly Craig | D35: =PROPER(TRIM(C35)) -> Kelly Craig | E35: Central | F35: =UPPER(TRIM(E35)) -> CENTRAL | G35: Furniture | H35: =PROPER(TRIM(G35)) -> Furniture | I35: 08-15-2025 | J35: 45884 | K35: 246.72 | L35: 246.72 | M35: =IF(L35>2500, "High Sales", "Low Sales") -> Low Sales | N35: =IF(OR(ISBLANK(L35), L35="", L35=0), "Grade C", IF(L35>=4000, "Grade A", IF(L35>=2000, "Grade B", "Grade C"))) -> Grade C | O35: 20 | P35: 20 | Q35: Returned | R35: 10 | S35: =CONCATENATE(OrdersTable[[#This Row],[Clean_ID]],"-",OrdersTable[[#This Row],[Clean_Region]],"-",OrdersTable[[#This Row],[Clean_Product]]) -> 1033-CENTRAL-Furniture
A36: ORD1034 | B36: =RIGHT(A36, 4) -> 1034 | C36: Deborah Rodriguez | D36: =PROPER(TRIM(C36)) -> Deborah Rodriguez | E36: Central | F36: =UPPER(TRIM(E36)) -> CENTRAL | G36: Office Supplies | H36: =PROPER(TRIM(G36)) -> Office Supplies | I36: 2024-09-24 | J36: 45559 | L36: 0 | M36: =IF(L36>2500, "High Sales", "Low Sales") -> Low Sales | N36: =IF(OR(ISBLANK(L36), L36="", L36=0), "Grade C", IF(L36>=4000, "Grade A", IF(L36>=2000, "Grade B", "Grade C"))) -> Grade C | O36: 10 | P36: 10 | Q36: Cancelled | R36: 7 | S36: =CONCATENATE(OrdersTable[[#This Row],[Clean_ID]],"-",OrdersTable[[#This Row],[Clean_Region]],"-",OrdersTable[[#This Row],[Clean_Product]]) -> 1034-CENTRAL-Office Supplies
A37: ORD1035 | B37: =RIGHT(A37, 4) -> 1035 | C37: Tammy Mckay | D37: =PROPER(TRIM(C37)) -> Tammy Mckay | E37: South | F37: =UPPER(TRIM(E37)) -> SOUTH | G37: Office Supplies | H37: =PROPER(TRIM(G37)) -> Office Supplies | I37: 13/04/2025 | J37: 45760 | K37: 4648.64 | L37: 4648.64 | M37: =IF(L37>2500, "High Sales", "Low Sales") -> High Sales | N37: =IF(OR(ISBLANK(L37), L37="", L37=0), "Grade C", IF(L37>=4000, "Grade A", IF(L37>=2000, "Grade B", "Grade C"))) -> Grade A | O37: 5 | P37: 5 | Q37: Shipped | R37: 10 | S37: =CONCATENATE(OrdersTable[[#This Row],[Clean_ID]],"-",OrdersTable[[#This Row],[Clean_Region]],"-",OrdersTable[[#This Row],[Clean_Product]]) -> 1035-SOUTH-Office Supplies
A38: ORD1036 | B38: =RIGHT(A38, 4) -> 1036 | C38: Cynthia Crawford | D38: =PROPER(TRIM(C38)) -> Cynthia Crawford | E38: Central | F38: =UPPER(TRIM(E38)) -> CENTRAL | G38: Electronics | H38: =PROPER(TRIM(G38)) -> Electronics | I38: 03-16-2024 | J38: 45367 | L38: 0 | M38: =IF(L38>2500, "High Sales", "Low Sales") -> Low Sales | N38: =IF(OR(ISBLANK(L38), L38="", L38=0), "Grade C", IF(L38>=4000, "Grade A", IF(L38>=2000, "Grade B", "Grade C"))) -> Grade C | O38: 10 | P38: 10 | Q38: Cancelled | R38: 15 | S38: =CONCATENATE(OrdersTable[[#This Row],[Clean_ID]],"-",OrdersTable[[#This Row],[Clean_Region]],"-",OrdersTable[[#This Row],[Clean_Product]]) -> 1036-CENTRAL-Electronics
A39: ORD1037 | B39: =RIGHT(A39, 4) -> 1037 | C39: Benjamin Wright | D39: =PROPER(TRIM(C39)) -> Benjamin Wright | E39: North | F39: =UPPER(TRIM(E39)) -> NORTH | G39: Furniture | H39: =PROPER(TRIM(G39)) -> Furniture | I39: 13/01/2025 | J39: 45670 | L39: 0 | M39: =IF(L39>2500, "High Sales", "Low Sales") -> Low Sales | N39: =IF(OR(ISBLANK(L39), L39="", L39=0), "Grade C", IF(L39>=4000, "Grade A", IF(L39>=2000, "Grade B", "Grade C"))) -> Grade C | P39: 0 | Q39: Returned | R39: 1 | S39: =CONCATENATE(OrdersTable[[#This Row],[Clean_ID]],"-",OrdersTable[[#This Row],[Clean_Region]],"-",OrdersTable[[#This Row],[Clean_Product]]) -> 1037-NORTH-Furniture
A40: ORD1038 | B40: =RIGHT(A40, 4) -> 1038 | C40: Ryan Blake | D40: =PROPER(TRIM(C40)) -> Ryan Blake | E40: north | F40: =UPPER(TRIM(E40)) -> NORTH | G40: Office Supplies | H40: =PROPER(TRIM(G40)) -> Office Supplies | I40: 2025-11-10 | J40: 45971 | K40: 4697.7 | L40: 4697.7 | M40: =IF(L40>2500, "High Sales", "Low Sales") -> High Sales | N40: =IF(OR(ISBLANK(L40), L40="", L40=0), "Grade C", IF(L40>=4000, "Grade A", IF(L40>=2000, "Grade B", "Grade C"))) -> Grade A | O40: 15 | P40: 15 | Q40: Delivered | R40: 15 | S40: =CONCATENATE(OrdersTable[[#This Row],[Clean_ID]],"-",OrdersTable[[#This Row],[Clean_Region]],"-",OrdersTable[[#This Row],[Clean_Product]]) -> 1038-NORTH-Office Supplies
...

Sheet Inventory
A1: Product_ID | B1: Product_Name | C1: Clean_Name | D1: Warehouse | E1: Clean_Warehouse | F1: Stock_Qty | G1: Clean_Stock | H1: Reorder_Level | I1: Unit_Cost | J1: Supplier_ID | K1: Inventory_Status | N1: Matching products with warehouses
A2: PRD1 | B2: Man | C2: =PROPER(TRIM(B2)) -> Man | D2: WH-B | E2: =PROPER(TRIM(D2)) -> Wh-B | G2: 0 | H2: 189 | I2: 222.48 | J2: SUP67 | K2: =IF(OR(ISBLANK(G2), G2<=H2), "Low Stock - Reorder", "Healthy Stock") -> Low Stock - Reorder | N2: =INDEX(Inventory!D:D, MATCH(A12, Inventory!A:A, 0)) -> WH-C
A3: PRD2 | B3: Sport | C3: =PROPER(TRIM(B3)) -> Sport | D3: WH-C | E3: =PROPER(TRIM(D3)) -> Wh-C | G3: 0 | H3: 104 | I3: 199.5 | J3: SUP10 | K3: =IF(OR(ISBLANK(G3), G3<=H3), "Low Stock - Reorder", "Healthy Stock") -> Low Stock - Reorder
A4: PRD3 | B4: Financial | C4: =PROPER(TRIM(B4)) -> Financial | D4: wh-a | E4: =PROPER(TRIM(D4)) -> Wh-A | F4: 207 | G4: 207 | H4: 54 | I4: 426.71 | J4: SUP38 | K4: =IF(OR(ISBLANK(G4), G4<=H4), "Low Stock - Reorder", "Healthy Stock") -> Healthy Stock
A5: PRD4 | B5: Final | C5: =PROPER(TRIM(B5)) -> Final | D5: wh-a | E5: =PROPER(TRIM(D5)) -> Wh-A | F5: 42 | G5: 42 | H5: 170 | I5: 83.06 | J5: SUP51 | K5: =IF(OR(ISBLANK(G5), G5<=H5), "Low Stock - Reorder", "Healthy Stock") -> Low Stock - Reorder
A6: PRD5 | B6: Course | C6: =PROPER(TRIM(B6)) -> Course | D6: WH-B | E6: =PROPER(TRIM(D6)) -> Wh-B | F6: 526 | G6: 526 | H6: 110 | I6: 472.62 | J6: SUP90 | K6: =IF(OR(ISBLANK(G6), G6<=H6), "Low Stock - Reorder", "Healthy Stock") -> Healthy Stock
A7: PRD6 | B7: Page | C7: =PROPER(TRIM(B7)) -> Page | D7: wh-a | E7: =PROPER(TRIM(D7)) -> Wh-A | F7: 319 | G7: 319 | H7: 181 | I7: 413.56 | J7: SUP37 | K7: =IF(OR(ISBLANK(G7), G7<=H7), "Low Stock - Reorder", "Healthy Stock") -> Healthy Stock
A8: PRD7 | B8: Course | C8: =PROPER(TRIM(B8)) -> Course | D8: wh-a | E8: =PROPER(TRIM(D8)) -> Wh-A | F8: 288 | G8: 288 | H8: 73 | I8: 219.39 | J8: SUP31 | K8: =IF(OR(ISBLANK(G8), G8<=H8), "Low Stock - Reorder", "Healthy Stock") -> Healthy Stock
A9: PRD8 | B9: Address | C9: =PROPER(TRIM(B9)) -> Address | D9: WH-C | E9: =PROPER(TRIM(D9)) -> Wh-C | F9: 873 | G9: 873 | H9: 58 | I9: 118.23 | J9: SUP13 | K9: =IF(OR(ISBLANK(G9), G9<=H9), "Low Stock - Reorder", "Healthy Stock") -> Healthy Stock
A10: PRD9 | B10: Seem | C10: =PROPER(TRIM(B10)) -> Seem | D10: WH-A | E10: =PROPER(TRIM(D10)) -> Wh-A | F10: 730 | G10: 730 | H10: 149 | I10: 208.96 | J10: SUP99 | K10: =IF(OR(ISBLANK(G10), G10<=H10), "Low Stock - Reorder", "Healthy Stock") -> Healthy Stock
A11: PRD10 | B11: Street | C11: =PROPER(TRIM(B11)) -> Street | D11: wh-a | E11: =PROPER(TRIM(D11)) -> Wh-A | F11: 441 | G11: 441 | H11: 86 | I11: 264.46 | J11: SUP47 | K11: =IF(OR(ISBLANK(G11), G11<=H11), "Low Stock - Reorder", "Healthy Stock") -> Healthy Stock
A12: PRD11 | B12: Music | C12: =PROPER(TRIM(B12)) -> Music | D12: WH-C | E12: =PROPER(TRIM(D12)) -> Wh-C | F12: 313 | G12: 313 | H12: 124 | I12: 376.31 | J12: SUP69 | K12: =IF(OR(ISBLANK(G12), G12<=H12), "Low Stock - Reorder", "Healthy Stock") -> Healthy Stock
A13: PRD12 | B13: Involve | C13: =PROPER(TRIM(B13)) -> Involve | D13: WH-C | E13: =PROPER(TRIM(D13)) -> Wh-C | G13: 0 | H13: 88 | I13: 85.61 | J13: SUP74 | K13: =IF(OR(ISBLANK(G13), G13<=H13), "Low Stock - Reorder", "Healthy Stock") -> Low Stock - Reorder
A14: PRD13 | B14: Idea | C14: =PROPER(TRIM(B14)) -> Idea | D14: WH-C | E14: =PROPER(TRIM(D14)) -> Wh-C | F14: Unknown | G14: 0 | H14: 50 | I14: 258.17 | J14: SUP68 | K14: =IF(OR(ISBLANK(G14), G14<=H14), "Low Stock - Reorder", "Healthy Stock") -> Low Stock - Reorder
A15: PRD14 | B15: Beat | C15: =PROPER(TRIM(B15)) -> Beat | D15: wh-a | E15: =PROPER(TRIM(D15)) -> Wh-A | F15: 81 | G15: 81 | H15: 147 | I15: 366.9 | J15: SUP100 | K15: =IF(OR(ISBLANK(G15), G15<=H15), "Low Stock - Reorder", "Healthy Stock") -> Low Stock - Reorder
A16: PRD15 | B16: Whether | C16: =PROPER(TRIM(B16)) -> Whether | D16: wh-a | E16: =PROPER(TRIM(D16)) -> Wh-A | F16: 765 | G16: 765 | H16: 65 | I16: 95.41 | J16: SUP50 | K16: =IF(OR(ISBLANK(G16), G16<=H16), "Low Stock - Reorder", "Healthy Stock") -> Healthy Stock
A17: PRD16 | B17: Speech | C17: =PROPER(TRIM(B17)) -> Speech | D17: WH-A | E17: =PROPER(TRIM(D17)) -> Wh-A | G17: 0 | H17: 54 | I17: 320.39 | J17: SUP57 | K17: =IF(OR(ISBLANK(G17), G17<=H17), "Low Stock - Reorder", "Healthy Stock") -> Low Stock - Reorder
A18: PRD17 | B18: Recently | C18: =PROPER(TRIM(B18)) -> Recently | D18: WH-C | E18: =PROPER(TRIM(D18)) -> Wh-C | G18: 0 | H18: 101 | I18: 258 | J18: SUP82 | K18: =IF(OR(ISBLANK(G18), G18<=H18), "Low Stock - Reorder", "Healthy Stock") -> Low Stock - Reorder
A19: PRD18 | B19: Call | C19: =PROPER(TRIM(B19)) -> Call | D19: WH-A | E19: =PROPER(TRIM(D19)) -> Wh-A | G19: 0 | H19: 84 | I19: 451.25 | J19: SUP36 | K19: =IF(OR(ISBLANK(G19), G19<=H19), "Low Stock - Reorder", "Healthy Stock") -> Low Stock - Reorder
A20: PRD19 | B20: Character | C20: =PROPER(TRIM(B20)) -> Character | D20: WH-A | E20: =PROPER(TRIM(D20)) -> Wh-A | F20: 987 | G20: 987 | H20: 156 | I20: 197.49 | J20: SUP63 | K20: =IF(OR(ISBLANK(G20), G20<=H20), "Low Stock - Reorder", "Healthy Stock") -> Healthy Stock
A21: PRD20 | B21: Street | C21: =PROPER(TRIM(B21)) -> Street | D21: WH-C | E21: =PROPER(TRIM(D21)) -> Wh-C | G21: 0 | H21: 106 | I21: 424.94 | J21: SUP19 | K21: =IF(OR(ISBLANK(G21), G21<=H21), "Low Stock - Reorder", "Healthy Stock") -> Low Stock - Reorder
A22: PRD21 | B22: Tonight | C22: =PROPER(TRIM(B22)) -> Tonight | D22: WH-A | E22: =PROPER(TRIM(D22)) -> Wh-A | G22: 0 | H22: 64 | I22: 438.05 | J22: SUP88 | K22: =IF(OR(ISBLANK(G22), G22<=H22), "Low Stock - Reorder", "Healthy Stock") -> Low Stock - Reorder
A23: PRD22 | B23: Third | C23: =PROPER(TRIM(B23)) -> Third | D23: WH-C | E23: =PROPER(TRIM(D23)) -> Wh-C | F23: 156 | G23: 156 | H23: 184 | I23: 288.26 | J23: SUP45 | K23: =IF(OR(ISBLANK(G23), G23<=H23), "Low Stock - Reorder", "Healthy Stock") -> Low Stock - Reorder
A24: PRD23 | B24: Nice | C24: =PROPER(TRIM(B24)) -> Nice | D24: WH-C | E24: =PROPER(TRIM(D24)) -> Wh-C | G24: 0 | H24: 53 | I24: 233.15 | J24: SUP9 | K24: =IF(OR(ISBLANK(G24), G24<=H24), "Low Stock - Reorder", "Healthy Stock") -> Low Stock - Reorder
A25: PRD24 | B25: Same | C25: =PROPER(TRIM(B25)) -> Same | D25: WH-A | E25: =PROPER(TRIM(D25)) -> Wh-A | G25: 0 | H25: 93 | I25: 310.19 | J25: SUP48 | K25: =IF(OR(ISBLANK(G25), G25<=H25), "Low Stock - Reorder", "Healthy Stock") -> Low Stock - Reorder
A26: PRD25 | B26: Newspaper | C26: =PROPER(TRIM(B26)) -> Newspaper | D26: WH-A | E26: =PROPER(TRIM(D26)) -> Wh-A | F26: 172 | G26: 172 | H26: 56 | I26: 495.28 | J26: SUP82 | K26: =IF(OR(ISBLANK(G26), G26<=H26), "Low Stock - Reorder", "Healthy Stock") -> Healthy Stock
A27: PRD26 | B27: Surface | C27: =PROPER(TRIM(B27)) -> Surface | D27: WH-A | E27: =PROPER(TRIM(D27)) -> Wh-A | G27: 0 | H27: 161 | I27: 225.03 | J27: SUP33 | K27: =IF(OR(ISBLANK(G27), G27<=H27), "Low Stock - Reorder", "Healthy Stock") -> Low Stock - Reorder
A28: PRD27 | B28: Everybody | C28: =PROPER(TRIM(B28)) -> Everybody | D28: WH-C | E28: =PROPER(TRIM(D28)) -> Wh-C | F28: 239 | G28: 239 | H28: 100 | I28: 389.22 | J28: SUP64 | K28: =IF(OR(ISBLANK(G28), G28<=H28), "Low Stock - Reorder", "Healthy Stock") -> Healthy Stock
A29: PRD28 | B29: Maintain | C29: =PROPER(TRIM(B29)) -> Maintain | D29: WH-A | E29: =PROPER(TRIM(D29)) -> Wh-A | G29: 0 | H29: 197 | I29: 381.38 | J29: SUP46 | K29: =IF(OR(ISBLANK(G29), G29<=H29), "Low Stock - Reorder", "Healthy Stock") -> Low Stock - Reorder
A30: PRD29 | B30: Religious | C30: =PROPER(TRIM(B30)) -> Religious | D30: WH-C | E30: =PROPER(TRIM(D30)) -> Wh-C | F30: 753 | G30: 753 | H30: 93 | I30: 283.64 | J30: SUP71 | K30: =IF(OR(ISBLANK(G30), G30<=H30), "Low Stock - Reorder", "Healthy Stock") -> Healthy Stock
A31: PRD30 | B31: Well | C31: =PROPER(TRIM(B31)) -> Well | D31: WH-B | E31: =PROPER(TRIM(D31)) -> Wh-B | F31: 299 | G31: 299 | H31: 90 | I31: 7.86 | J31: SUP24 | K31: =IF(OR(ISBLANK(G31), G31<=H31), "Low Stock - Reorder", "Healthy Stock") -> Healthy Stock
A32: PRD31 | B32: Use | C32: =PROPER(TRIM(B32)) -> Use | D32: WH-A | E32: =PROPER(TRIM(D32)) -> Wh-A | F32: 365 | G32: 365 | H32: 62 | I32: 256.96 | J32: SUP88 | K32: =IF(OR(ISBLANK(G32), G32<=H32), "Low Stock - Reorder", "Healthy Stock") -> Healthy Stock
A33: PRD32 | B33: Use | C33: =PROPER(TRIM(B33)) -> Use | D33: WH-C | E33: =PROPER(TRIM(D33)) -> Wh-C | F33: 142 | G33: 142 | H33: 162 | I33: 437.11 | J33: SUP71 | K33: =IF(OR(ISBLANK(G33), G33<=H33), "Low Stock - Reorder", "Healthy Stock") -> Low Stock - Reorder
A34: PRD33 | B34: Free | C34: =PROPER(TRIM(B34)) -> Free | D34: WH-A | E34: =PROPER(TRIM(D34)) -> Wh-A | F34: 123 | G34: 123 | H34: 156 | I34: 305.6 | J34: SUP22 | K34: =IF(OR(ISBLANK(G34), G34<=H34), "Low Stock - Reorder", "Healthy Stock") -> Low Stock - Reorder
A35: PRD34 | B35: Old | C35: =PROPER(TRIM(B35)) -> Old | D35: WH-C | E35: =PROPER(TRIM(D35)) -> Wh-C | F35: 988 | G35: 988 | H35: 133 | I35: 380.83 | J35: SUP62 | K35: =IF(OR(ISBLANK(G35), G35<=H35), "Low Stock - Reorder", "Healthy Stock") -> Healthy Stock
A36: PRD35 | B36: Sea | C36: =PROPER(TRIM(B36)) -> Sea | D36: WH-B | E36: =PROPER(TRIM(D36)) -> Wh-B | F36: 729 | G36: 729 | H36: 121 | I36: 376.17 | J36: SUP77 | K36: =IF(OR(ISBLANK(G36), G36<=H36), "Low Stock - Reorder", "Healthy Stock") -> Healthy Stock
A37: PRD36 | B37: Color | C37: =PROPER(TRIM(B37)) -> Color | D37: WH-A | E37: =PROPER(TRIM(D37)) -> Wh-A | G37: 0 | H37: 111 | I37: 31.82 | J37: SUP89 | K37: =IF(OR(ISBLANK(G37), G37<=H37), "Low Stock - Reorder", "Healthy Stock") -> Low Stock - Reorder
A38: PRD37 | B38: So | C38: =PROPER(TRIM(B38)) -> So | D38: WH-B | E38: =PROPER(TRIM(D38)) -> Wh-B | F38: 374 | G38: 374 | H38: 93 | I38: 245.74 | J38: SUP77 | K38: =IF(OR(ISBLANK(G38), G38<=H38), "Low Stock - Reorder", "Healthy Stock") -> Healthy Stock
A39: PRD38 | B39: Surface | C39: =PROPER(TRIM(B39)) -> Surface | D39: wh-a | E39: =PROPER(TRIM(D39)) -> Wh-A | F39: 833 | G39: 833 | H39: 111 | I39: 282.77 | J39: SUP65 | K39: =IF(OR(ISBLANK(G39), G39<=H39), "Low Stock - Reorder", "Healthy Stock") -> Healthy Stock
A40: PRD39 | B40: Reveal | C40: =PROPER(TRIM(B40)) -> Reveal | D40: WH-C | E40: =PROPER(TRIM(D40)) -> Wh-C | F40: 302 | G40: 302 | H40: 109 | I40: 243.51 | J40: SUP51 | K40: =IF(OR(ISBLANK(G40), G40<=H40), "Low Stock - Reorder", "Healthy Stock") -> Healthy Stock
...

Sheet Employees
A1: Emp_ID | B1: Employee_Name | C1: Clean_Name | D1: Department | E1: Clean_Department | F1: Salary | G1: Clean_Salary | H1: Joining_Date | I1: Clean_Date | J1: Performance_Score | K1: Performance_Category | L1: Average Salary | M1: =AVERAGE(G2:G401) -> 90115.762
A2: EMP1 | B2: Lauren West | C2: =PROPER(TRIM(B2)) -> Lauren West | D2: Finance | E2: =IF(UPPER(TRIM(D2))="IT", "IT", IF(UPPER(TRIM(D2))="HR", "HR", PROPER(TRIM(D2)))) -> Finance | F2: 46457 | G2: 46457 | H2: 10-06-2025 | I2: 45818 | J2: 4.3 | K2: =IF(J2>=4, "Excellent", IF(AND(J2>=2.5, J2<4), "Satisfactory", "Needs Improvement")) -> Excellent | L2: Average Sales Department Salary | M2: =AVERAGEIF(Employees!E:E, "Sales", Employees!G:G) -> 90746.986
A3: EMP2 | B3: Brandon Bauer | C3: =PROPER(TRIM(B3)) -> Brandon Bauer | D3: Sales | E3: =IF(UPPER(TRIM(D3))="IT", "IT", IF(UPPER(TRIM(D3))="HR", "HR", PROPER(TRIM(D3)))) -> Sales | F3: 47537 | G3: 47537 | H3: 22-05-2025 | I3: 45799 | J3: 3.8 | K3: =IF(J3>=4, "Excellent", IF(AND(J3>=2.5, J3<4), "Satisfactory", "Needs Improvement")) -> Satisfactory
A4: EMP3 | B4: Blake Keller | C4: =PROPER(TRIM(B4)) -> Blake Keller | D4: Sales | E4: =IF(UPPER(TRIM(D4))="IT", "IT", IF(UPPER(TRIM(D4))="HR", "HR", PROPER(TRIM(D4)))) -> Sales | F4: 56939 | G4: 56939 | H4: 12-04-2024 | I4: 45394 | J4: 2.9 | K4: =IF(J4>=4, "Excellent", IF(AND(J4>=2.5, J4<4), "Satisfactory", "Needs Improvement")) -> Satisfactory | L4: Vlookup | M4: Name | N4: Department
A5: EMP4 | B5: Michelle Bates MD | C5: =PROPER(TRIM(B5)) -> Michelle Bates Md | D5: sales | E5: =IF(UPPER(TRIM(D5))="IT", "IT", IF(UPPER(TRIM(D5))="HR", "HR", PROPER(TRIM(D5)))) -> Sales | F5: 148328 | G5: 148328 | H5: 04-02-2024 | I5: 45326 | J5: 1.5 | K5: =IF(J5>=4, "Excellent", IF(AND(J5>=2.5, J5<4), "Satisfactory", "Needs Improvement")) -> Needs Improvement | M5: =VLOOKUP(A5, Employees!A:D, 3, FALSE) -> Michelle Bates Md | N5: =VLOOKUP(A5, Employees!A:D, 4, FALSE) -> sales
A6: EMP5 | B6: Joshua Taylor | C6: =PROPER(TRIM(B6)) -> Joshua Taylor | D6: sales | E6: =IF(UPPER(TRIM(D6))="IT", "IT", IF(UPPER(TRIM(D6))="HR", "HR", PROPER(TRIM(D6)))) -> Sales | F6: 39734 | G6: 39734 | H6: 15-02-2024 | I6: 45337 | J6: 4.8 | K6: =IF(J6>=4, "Excellent", IF(AND(J6>=2.5, J6<4), "Satisfactory", "Needs Improvement")) -> Excellent
A7: EMP6 | B7: Bryan Huffman | C7: =PROPER(TRIM(B7)) -> Bryan Huffman | D7: HR | E7: =IF(UPPER(TRIM(D7))="IT", "IT", IF(UPPER(TRIM(D7))="HR", "HR", PROPER(TRIM(D7)))) -> HR | F7: 132390 | G7: 132390 | H7: 08-10-2025 | I7: 45938 | J7: 4.4 | K7: =IF(J7>=4, "Excellent", IF(AND(J7>=2.5, J7<4), "Satisfactory", "Needs Improvement")) -> Excellent
A8: EMP7 | B8: Angela Booker | C8: =PROPER(TRIM(B8)) -> Angela Booker | D8: IT | E8: =IF(UPPER(TRIM(D8))="IT", "IT", IF(UPPER(TRIM(D8))="HR", "HR", PROPER(TRIM(D8)))) -> IT | F8: 60463 | G8: 60463 | H8: 30-04-2026 | I8: 46142 | J8: 2.2 | K8: =IF(J8>=4, "Excellent", IF(AND(J8>=2.5, J8<4), "Satisfactory", "Needs Improvement")) -> Needs Improvement
A9: EMP8 | B9: Norma Floyd | C9: =PROPER(TRIM(B9)) -> Norma Floyd | D9: Sales | E9: =IF(UPPER(TRIM(D9))="IT", "IT", IF(UPPER(TRIM(D9))="HR", "HR", PROPER(TRIM(D9)))) -> Sales | F9: 57214 | G9: 57214 | H9: 13-10-2024 | I9: 45578 | J9: 3.7 | K9: =IF(J9>=4, "Excellent", IF(AND(J9>=2.5, J9<4), "Satisfactory", "Needs Improvement")) -> Satisfactory
A10: EMP9 | B10: Andrew Thompson | C10: =PROPER(TRIM(B10)) -> Andrew Thompson | D10: HR | E10: =IF(UPPER(TRIM(D10))="IT", "IT", IF(UPPER(TRIM(D10))="HR", "HR", PROPER(TRIM(D10)))) -> HR | F10: 53784 | G10: 53784 | H10: 27-10-2025 | I10: 45957 | J10: 5 | K10: =IF(J10>=4, "Excellent", IF(AND(J10>=2.5, J10<4), "Satisfactory", "Needs Improvement")) -> Excellent
A11: EMP10 | B11: Anthony Romero | C11: =PROPER(TRIM(B11)) -> Anthony Romero | D11: sales | E11: =IF(UPPER(TRIM(D11))="IT", "IT", IF(UPPER(TRIM(D11))="HR", "HR", PROPER(TRIM(D11)))) -> Sales | F11: 79199 | G11: 79199 | H11: 01-08-2024 | I11: 45505 | J11: 2 | K11: =IF(J11>=4, "Excellent", IF(AND(J11>=2.5, J11<4), "Satisfactory", "Needs Improvement")) -> Needs Improvement
A12: EMP11 | B12: Michael Meyers | C12: =PROPER(TRIM(B12)) -> Michael Meyers | D12: Operations | E12: =IF(UPPER(TRIM(D12))="IT", "IT", IF(UPPER(TRIM(D12))="HR", "HR", PROPER(TRIM(D12)))) -> Operations | F12: 82177 | G12: 82177 | H12: 11-10-2024 | I12: 45576 | J12: 1.3 | K12: =IF(J12>=4, "Excellent", IF(AND(J12>=2.5, J12<4), "Satisfactory", "Needs Improvement")) -> Needs Improvement
A13: EMP12 | B13: Billy Turner | C13: =PROPER(TRIM(B13)) -> Billy Turner | D13: IT | E13: =IF(UPPER(TRIM(D13))="IT", "IT", IF(UPPER(TRIM(D13))="HR", "HR", PROPER(TRIM(D13)))) -> IT | F13: 113665 | G13: 113665 | H13: 02-07-2024 | I13: 45475 | J13: 3.4 | K13: =IF(J13>=4, "Excellent", IF(AND(J13>=2.5, J13<4), "Satisfactory", "Needs Improvement")) -> Satisfactory
A14: EMP13 | B14: Tammy Price | C14: =PROPER(TRIM(B14)) -> Tammy Price | D14: Finance | E14: =IF(UPPER(TRIM(D14))="IT", "IT", IF(UPPER(TRIM(D14))="HR", "HR", PROPER(TRIM(D14)))) -> Finance | F14: 117027 | G14: 117027 | H14: 22-05-2025 | I14: 45799 | J14: 1.2 | K14: =IF(J14>=4, "Excellent", IF(AND(J14>=2.5, J14<4), "Satisfactory", "Needs Improvement")) -> Needs Improvement
A15: EMP14 | B15: David Riley | C15: =PROPER(TRIM(B15)) -> David Riley | D15: Sales | E15: =IF(UPPER(TRIM(D15))="IT", "IT", IF(UPPER(TRIM(D15))="HR", "HR", PROPER(TRIM(D15)))) -> Sales | F15: 73355 | G15: 73355 | H15: 03-06-2024 | I15: 45446 | J15: 1.4 | K15: =IF(J15>=4, "Excellent", IF(AND(J15>=2.5, J15<4), "Satisfactory", "Needs Improvement")) -> Needs Improvement
A16: EMP15 | B16: Frank Lewis | C16: =PROPER(TRIM(B16)) -> Frank Lewis | D16: sales | E16: =IF(UPPER(TRIM(D16))="IT", "IT", IF(UPPER(TRIM(D16))="HR", "HR", PROPER(TRIM(D16)))) -> Sales | F16: 124641 | G16: 124641 | H16: 31-03-2024 | I16: 45382 | J16: 2.1 | K16: =IF(J16>=4, "Excellent", IF(AND(J16>=2.5, J16<4), "Satisfactory", "Needs Improvement")) -> Needs Improvement
A17: EMP16 | B17: Jordan Wallace | C17: =PROPER(TRIM(B17)) -> Jordan Wallace | D17: sales | E17: =IF(UPPER(TRIM(D17))="IT", "IT", IF(UPPER(TRIM(D17))="HR", "HR", PROPER(TRIM(D17)))) -> Sales | G17: 0 | H17: 21-08-2024 | I17: 45525 | J17: 4.8 | K17: =IF(J17>=4, "Excellent", IF(AND(J17>=2.5, J17<4), "Satisfactory", "Needs Improvement")) -> Excellent
A18: EMP17 | B18: Susan Rollins | C18: =PROPER(TRIM(B18)) -> Susan Rollins | D18: HR | E18: =IF(UPPER(TRIM(D18))="IT", "IT", IF(UPPER(TRIM(D18))="HR", "HR", PROPER(TRIM(D18)))) -> HR | F18: 92239 | G18: 92239 | H18: 13-05-2024 | I18: 45425 | J18: 3.6 | K18: =IF(J18>=4, "Excellent", IF(AND(J18>=2.5, J18<4), "Satisfactory", "Needs Improvement")) -> Satisfactory
A19: EMP18 | B19: Thomas Green | C19: =PROPER(TRIM(B19)) -> Thomas Green | D19: sales | E19: =IF(UPPER(TRIM(D19))="IT", "IT", IF(UPPER(TRIM(D19))="HR", "HR", PROPER(TRIM(D19)))) -> Sales | F19: 79981 | G19: 79981 | H19: 03-06-2025 | I19: 45811 | J19: 2.5 | K19: =IF(J19>=4, "Excellent", IF(AND(J19>=2.5, J19<4), "Satisfactory", "Needs Improvement")) -> Satisfactory
A20: EMP19 | B20: Maria Walker | C20: =PROPER(TRIM(B20)) -> Maria Walker | D20: Operations | E20: =IF(UPPER(TRIM(D20))="IT", "IT", IF(UPPER(TRIM(D20))="HR", "HR", PROPER(TRIM(D20)))) -> Operations | F20: 125711 | G20: 125711 | H20: 01-02-2026 | I20: 46054 | J20: 4.2 | K20: =IF(J20>=4, "Excellent", IF(AND(J20>=2.5, J20<4), "Satisfactory", "Needs Improvement")) -> Excellent
A21: EMP20 | B21: Lisa Patton | C21: =PROPER(TRIM(B21)) -> Lisa Patton | D21: Operations | E21: =IF(UPPER(TRIM(D21))="IT", "IT", IF(UPPER(TRIM(D21))="HR", "HR", PROPER(TRIM(D21)))) -> Operations | F21: 100252 | G21: 100252 | H21: 07-01-2025 | I21: 45664 | J21: 1.7 | K21: =IF(J21>=4, "Excellent", IF(AND(J21>=2.5, J21<4), "Satisfactory", "Needs Improvement")) -> Needs Improvement
A22: EMP21 | B22: Dustin Greer | C22: =PROPER(TRIM(B22)) -> Dustin Greer | D22: HR | E22: =IF(UPPER(TRIM(D22))="IT", "IT", IF(UPPER(TRIM(D22))="HR", "HR", PROPER(TRIM(D22)))) -> HR | F22: 113034 | G22: 113034 | H22: 08-02-2026 | I22: 46061 | J22: 1.6 | K22: =IF(J22>=4, "Excellent", IF(AND(J22>=2.5, J22<4), "Satisfactory", "Needs Improvement")) -> Needs Improvement
A23: EMP22 | B23: Joseph Jackson | C23: =PROPER(TRIM(B23)) -> Joseph Jackson | D23: sales | E23: =IF(UPPER(TRIM(D23))="IT", "IT", IF(UPPER(TRIM(D23))="HR", "HR", PROPER(TRIM(D23)))) -> Sales | F23: 62219 | G23: 62219 | H23: 07-12-2024 | I23: 45633 | J23: 2.1 | K23: =IF(J23>=4, "Excellent", IF(AND(J23>=2.5, J23<4), "Satisfactory", "Needs Improvement")) -> Needs Improvement
A24: EMP23 | B24: Elizabeth Rangel | C24: =PROPER(TRIM(B24)) -> Elizabeth Rangel | D24: IT | E24: =IF(UPPER(TRIM(D24))="IT", "IT", IF(UPPER(TRIM(D24))="HR", "HR", PROPER(TRIM(D24)))) -> IT | F24: 50154 | G24: 50154 | H24: 21-06-2024 | I24: 45464 | J24: 2 | K24: =IF(J24>=4, "Excellent", IF(AND(J24>=2.5, J24<4), "Satisfactory", "Needs Improvement")) -> Needs Improvement
A25: EMP24 | B25: Brandon Wolfe | C25: =PROPER(TRIM(B25)) -> Brandon Wolfe | D25: Operations | E25: =IF(UPPER(TRIM(D25))="IT", "IT", IF(UPPER(TRIM(D25))="HR", "HR", PROPER(TRIM(D25)))) -> Operations | F25: 124932 | G25: 124932 | H25: 03-01-2025 | I25: 45660 | J25: 4.2 | K25: =IF(J25>=4, "Excellent", IF(AND(J25>=2.5, J25<4), "Satisfactory", "Needs Improvement")) -> Excellent
A26: EMP25 | B26: Hannah Ruiz | C26: =PROPER(TRIM(B26)) -> Hannah Ruiz | D26: Sales | E26: =IF(UPPER(TRIM(D26))="IT", "IT", IF(UPPER(TRIM(D26))="HR", "HR", PROPER(TRIM(D26)))) -> Sales | F26: 35958 | G26: 35958 | H26: 21-02-2026 | I26: 46074 | J26: 2.6 | K26: =IF(J26>=4, "Excellent", IF(AND(J26>=2.5, J26<4), "Satisfactory", "Needs Improvement")) -> Satisfactory
A27: EMP26 | B27: Joshua Scott | C27: =PROPER(TRIM(B27)) -> Joshua Scott | D27: HR | E27: =IF(UPPER(TRIM(D27))="IT", "IT", IF(UPPER(TRIM(D27))="HR", "HR", PROPER(TRIM(D27)))) -> HR | F27: 45194 | G27: 45194 | H27: 19-08-2024 | I27: 45523 | J27: 3.5 | K27: =IF(J27>=4, "Excellent", IF(AND(J27>=2.5, J27<4), "Satisfactory", "Needs Improvement")) -> Satisfactory
A28: EMP27 | B28: Christopher Sanchez | C28: =PROPER(TRIM(B28)) -> Christopher Sanchez | D28: HR | E28: =IF(UPPER(TRIM(D28))="IT", "IT", IF(UPPER(TRIM(D28))="HR", "HR", PROPER(TRIM(D28)))) -> HR | F28: 64909 | G28: 64909 | H28: 09-01-2025 | I28: 45666 | J28: 3.6 | K28: =IF(J28>=4, "Excellent", IF(AND(J28>=2.5, J28<4), "Satisfactory", "Needs Improvement")) -> Satisfactory
A29: EMP28 | B29: Patrick Lyons | C29: =PROPER(TRIM(B29)) -> Patrick Lyons | D29: Finance | E29: =IF(UPPER(TRIM(D29))="IT", "IT", IF(UPPER(TRIM(D29))="HR", "HR", PROPER(TRIM(D29)))) -> Finance | F29: 47721 | G29: 47721 | H29: 29-04-2025 | I29: 45776 | J29: 2.5 | K29: =IF(J29>=4, "Excellent", IF(AND(J29>=2.5, J29<4), "Satisfactory", "Needs Improvement")) -> Satisfactory
... A401: EMP400 | B401: Danielle Anderson | C401: =PROPER(TRIM(B401)) -> Danielle Anderson | D401: IT | E401: =IF(UPPER(TRIM(D401))="IT", "IT", IF(UPPER(TRIM(D401))="HR", "HR", PROPER(TRIM(D401)))) -> IT | F401: 74804 | G401: 74804 | H401: 04-07-2024 | I401: 45477 | J401: 3.3 | K401: =IF(J401>=4, "Excellent", IF(AND(J401>=2.5, J401<4), "Satisfactory", "Needs Improvement")) -> Satisfactory

Sheet Suppliers
A1: Supplier_ID | B1: Supplier_Name | C1: Country | D1: Lead_Time_Days | E1: Rating
A2: SUP1 | B2: Casey-Townsend | C2: Pakistan | D2: 33 | E2: 2.4
A3: SUP2 | B3: Anderson, Mahoney and Lane | C3: China | D3: 32 | E3: 2.5
A4: SUP3 | B4: Norris LLC | C4: Germany | D4: 24 | E4: 3.7
A5: SUP4 | B5: Jones-Fitzgerald | C5: Germany | D5: 3 | E5: 1.9
A6: SUP5 | B6: Sanchez Ltd | C6: Germany | D6: 40 | E6: 3.5
A7: SUP6 | B7: Patrick and Sons | C7: UAE | D7: 39 | E7: 2
A8: SUP7 | B8: Murphy-Carter | C8: Pakistan | D8: 26 | E8: 3.5
A9: SUP8 | B9: Hoffman-Cooper | C9: Germany | D9: 18 | E9: 2.6
A10: SUP9 | B10: Armstrong, Paul and Thompson | C10: Germany | D10: 13 | E10: 1.7
A11: SUP10 | B11: Ferguson, Mcpherson and Wheeler | C11: USA | D11: 40 | E11: 2
A12: SUP11 | B12: Collins, Reynolds and Chen | C12: USA | D12: 24 | E12: 2
A13: SUP12 | B13: Walton-Williams | C13: Germany | D13: 34 | E13: 4.5
... A101: SUP100 | B101: Espinoza-Sims | C101: UAE | D101: 11 | E101: 4

Sheet Logistics
A1: Shipment_ID | B1: Carrier | C1: Shipment_Date | D1: Clean_Date | E1: Transport_Cost | F1: Delivery_Status | I1: Highest Transport Cost | J1: =MAX(E2:E2001) -> 9992.22
A2: SHP1 | B2: DHL | C2: 2025/09/20 | D2: 45920 | E2: 8312.13 | F2: Delayed | I2: Lowest Transport Cost | J2: =MIN(E2:E2001) -> 100.77
A3: SHP2 | B3: TCS | C3: 2024/09/25 | D3: 45560 | E3: 9574.38 | F3: Lost | I3: Total Delayed Shipments | J3: =COUNTIF(Logistics!F:F, "Delayed") -> 694
A4: SHP3 | B4: UPS | C4: 2024/02/21 | D4: 45343 | E4: 4365.58 | F4: Lost
A5: SHP4 | B5: TCS | C5: 2025/07/08 | D5: 45846 | E5: 9006.67 | F5: On Time
A6: SHP5 | B6: FedEx | C6: 2025/05/29 | D6: 45806 | E6: 4853.3 | F6: On Time
A7: SHP6 | B7: DHL | C7: 2024/05/21 | D7: 45433 | E7: 9317.41 | F7: On Time
A8: SHP7 | B8: FedEx | C8: 2026/01/10 | D8: 46032 | E8: 5961.25 | F8: Lost
A9: SHP8 | B9: FedEx | C9: 2025/08/24 | D9: 45893 | E9: 7591.38 | F9: Lost
A10: SHP9 | B10: DHL | C10: 2024/04/17 | D10: 45399 | E10: 3753.9 | F10: On Time
A11: SHP10 | B11: UPS | C11: 2025/09/28 | D11: 45928 | E11: 3558.83 | F11: Delayed
A12: SHP11 | B12: TCS | C12: 2025/03/12 | D12: 45728 | E12: 878.39 | F12: Lost
A13: SHP12 | B13: DHL | C13: 2026/01/10 | D13: 46032 | E13: 6317.87 | F13: Delayed
A14: SHP13 | B14: DHL | C14: 2024/08/31 | D14: 45535 | E14: 477.41 | F14: Lost
A15: SHP14 | B15: DHL | C15: 2024/01/07 | D15: 45298 | E15: 8657.88 | F15: Delayed
... A2001: SHP2000 | B2001: DHL | C2001: 2025/09/09 | D2001: 45909 | E2001: 1932.71 | F2001: Lost

Sheet Returns
A1: Return_ID | B1: Order_ID | C1: Reason | D1: Refund_Amount | E1: Return_Date | F1: Clean_Return_Date
A2: RET1 | B2: ORD5988 | C2: Damaged | D2: 868.39 | E2: 03/18/2026 | F2: 46099 | H2: Damaged Returns | I2: =COUNTIF(Returns!C:C, "Damaged") -> 144
A3: RET2 | B3: ORD2836 | C3: Wrong Item | D3: 944.25 | E3: 05/14/2024 | F3: 45426
A4: RET3 | B4: ORD4079 | C4: Late Delivery | D4: 433.62 | E4: 08/03/2025 | F4: 45872
A5: RET4 | B5: ORD4851 | C5: Customer Changed Mind | D5: 552.58 | E5: 03/13/2024 | F5: 45364
A6: RET5 | B6: ORD2110 | C6: Customer Changed Mind | D6: 415.1 | E6: 11/30/2025 | F6: 45991
A7: RET6 | B7: ORD5753 | C7: Damaged | D7: 397.33 | E7: 08/10/2025 | F7: 45879
A8: RET7 | B8: ORD5641 | C8: Wrong Item | D8: 734.13 | E8: 04/13/2025 | F8: 45760
A9: RET8 | B9: ORD4711 | C9: Damaged | D9: 681.57 | E9: 05/29/2025 | F9: 45806
A10: RET9 | B10: ORD4476 | C10: Customer Changed Mind | D10: 367.99 | E10: 03/21/2026 | F10: 46102
A11: RET10 | B11: ORD3428 | C11: Customer Changed Mind | D11: 383.73 | E11: 09/03/2025 | F11: 45903
A12: RET11 | B12: ORD4685 | C12: Customer Changed Mind | D12: 670.34 | E12: 11/23/2024 | F12: 45619
A13: RET12 | B13: ORD5918 | C13: Customer Changed Mind | D13: 500.63 | E13: 05/08/2025 | F13: 45785
A14: RET13 | B14: ORD2752 | C14: Damaged | D14: 58.45 | E14: 04/18/2025 | F14: 45765
... A601: RET600 | B601: ORD2229 | C601: Wrong Item | D601: 485.25 | E601: 09/21/2024 | F601: 45556
